Workbook

Sheet Assumptions
A1: Onyx Accounting Group, LLC - 2026 Medical Plan Comparison
A2: All plans offered by ADP TotalSource, TriNet and Angle Health / CapFi. Medical effective 10/1/2026. Dental, vision, life and disability are priced separately and are NOT in this workbook.
A4: LEGEND
B5: Blue text = hardcoded input taken from a vendor document or from Josephine. These are the only cells to edit.
B6: Black text = formula. Recalculates from the blue inputs.
B7: Green text = link to another tab in this workbook.
A8: 1. ONYX EMPLOYER CONTRIBUTION TARGET (fixed dollars, medical only)
A9: Tier | B9: Code | C9: Onyx target $/mo | D9: Onyx target $/yr | E9: Notes
A10: Employee only | B10: EE | C10: 300 | D10: =C10*12 -> 3600 | E10: Set by Onyx. Applies to Lisa.
A11: Employee + spouse | B11: ES | C11: 600 | D11: =C11*12 -> 7200 | E11: Set by Onyx. Applies to Christine.
A12: Employee + child(ren) | B12: EC | C12: 600 | D12: =C12*12 -> 7200 | E12: ASSUMPTION - no target was stated for this tier and nobody occupies it today. Defaulted to the employee+spouse figure. Change if wrong.
A13: Family | B13: FAM | C13: 1000 | D13: =C13*12 -> 12000 | E13: Set by Onyx. Applies to Steven and Jessica.
A14: Target cost at current enrollment (4 enrolled) | C14: =SUMIFS(C10:C13,B10:B13,"EE")*1+SUMIFS(C10:C13,B10:B13,"ES")*1+SUMIFS(C10:C13,B10:B13,"FAM")*2 -> 2900 | D14: =C14*12 -> 34800
A16: 2. VENDOR EMPLOYER CONTRIBUTION FLOORS (minimum Onyx must pay per enrolled employee, applied flat to every tier)
A17: Vendor | B17: % required | C17: Reference plan employee-only premium | D17: Floor $/mo per enrolled EE | E17: Reference plan | F17: Source / status
A18: ADP | B18: 0.5 | C18: 374.03 | D18: =B18*C18 -> 187.015 | E18: OA EPO 8000-80% ValueINT | F18: Stated in writing: 50% of the lowest-cost plan, employee-only rate.
A19: TriNet | B19: 0.7 | C19: 385 | D19: =B19*C19 -> 269.5 | E19: Aetna ACO 6500 AZ | F19: CONFIRMED by TriNet: 70% of the minimum funding on the lowest-cost plan offered. Our derivation was right and reconciles to the penny on both carriers quoted. Keyed to the ACO 6500's $385 employee-only rate.
A20: Angle | B20: 0.5 | C20: 439.03 | D20: =B20*C20 -> 219.515 | E20: ANG HDHP 3400/5000 | F20: Level-funded minimum participation funding; 50% of the lowest employee-only rate.
A22: The floor only bites where it exceeds the tier target. At Onyx's targets it never does - every floor here is below $300 - so Onyx's stated dollars govern on all three vendors.
A23: Insperity is NOT in this workbook. Its floor mechanic is different (75% of a designated Base Plan's employee-only rate: $509.76 Saver / $646.90 Select) and it exceeds every tier target, so it cannot be compared on the same grid.
A25: 3. ENROLLMENT USED FOR THE TOTAL-COST TAB
A26: Employee | B26: Annual pay | C26: Medical tier | D26: Code | E26: Enrolling? | F26: Note
A27: Steven Nikolov | B27: 186000 | C27: Family | D27: FAM | E27: Yes | F27: 100% owner. >2% S-corp shareholder - premiums cannot run pretax through the cafeteria plan (IRC 1372). Whether he enrolls is still open; worth $12,000/yr of Onyx cost.
A28: Lisa Danforth | B28: 178094 | C28: Employee only | D28: EE | E28: Yes
A29: Jessica B. | B29: 135000 | C29: Family | D29: FAM | E29: Yes | F29: New hire.
A30: Christine Johnson | B30: 79228 | C30: Employee + spouse | D30: ES | E30: Yes
A31: Josephine Mack | B31: 80000 | C31: Family | D31: FAM | E31: No | F31: Waiving medical, dental and vision. Shown for reference only - if she enrolled it would be family coverage, +$12,000/yr to Onyx at every vendor.
A32: Elena Nikolov is not on payroll and is not an enrollee.
A34: 4. HOW EACH COLUMN IS CALCULATED
A35: Item | B35: Treatment
A36: Onyx pays $/mo | B36: Formula: MIN(premium, MAX(tier target, vendor floor)). The MIN stops Onyx from being shown as paying more than the premium; it does not bind on any plan here.
A37: Employee pays $/mo | B37: Formula: premium minus Onyx pays. This is the payroll deduction.
A38: Worst case, employee | B38: Formula: employee annual premium plus the household out-of-pocket maximum for that tier. Premiums never count toward an out-of-pocket maximum, so the two add without overlapping. Employee-only rows use the individual OOP max; all other tiers use the family OOP max.
A39: Out-of-pocket maximum | B39: In-network only. Every plan here covers preventive care at 100% before the deductible, so the worst case assumes a full year of non-preventive claims.
A40: Coinsurance | B40: Shown as the share the PLAN pays after the deductible. 100% means the plan pays everything after the deductible is met. Aetna's own documents state the member's share; those were converted.
A41: 'ded' / 'd' on a copay | B41: That copay or coinsurance applies only AFTER the deductible is satisfied.
A42: HSA-eligible | B42: Y only where the plan is designated an HDHP and charges no non-preventive copay before the deductible. HSA contributions are deliberately NOT modeled - Onyx cannot know what any employee will choose to fund, so a plan's true cost to an employee with an HSA is lower than the worst case shown.
A43: Premiums | B43: Composite rates as quoted for Onyx's actual census. Quote IDs: TriNet Q-00412887, Angle 400798. ADP rates from the TotalSource 2026 renewal deck.
A44: Not modeled | B44: Admin fees, workers' compensation, setup fees, dental, vision, life and disability. Those sit in the employer-only cost table in the Steven report, not here. This workbook is medical premium only.
A46: 5. OPEN ITEMS THAT COULD MOVE THESE NUMBERS
...

Sheet Plan Design
A1: Plan design - all 30 plans
A2: Monthly premiums are composite rates quoted for Onyx's census. Coinsurance is the share the PLAN pays after the deductible. 'ded' or 'd' means the copay applies only after the deductible.
O3: Monthly premium by tier
A4: Vendor | B4: Plan | C4: Key | D4: Network | E4: HSA | F4: Ded individual | G4: Ded family | H4: OOP max individual | I4: OOP max family | J4: Coins (plan pays) | K4: PCP visit | L4: Specialist | M4: Rx generic / preferred / non-preferred | N4: Emergency room | O4: EE | P4: ES | Q4: EC | R4: FAM
A5: ADP | B5: EPO HDHP 2000-100Copay TIF | C5: ADP|EPO HDHP 2000-100Copay TIF | D5: Aetna EPO - no out-of-network | E5: Y | F5: 2000 | G5: 4000 | H5: 3500 | I5: 7000 | J5: 1 | K5: ded then $30 | L5: ded then $60 | M5: $10d / $45d / $70d | N5: ded + $350 | O5: 640.66 | P5: 1377.42 | Q5: 1249.28 | R5: 1986.04
A6: ADP | B6: EPO HDHP 2500-100Copay TIF | C6: ADP|EPO HDHP 2500-100Copay TIF | D6: Aetna EPO - no out-of-network | E6: Y | F6: 2500 | G6: 5000 | H6: 3500 | I6: 7000 | J6: 1 | K6: ded then $30 | L6: ded then $60 | M6: $10d / $45d / $70d | N6: ded + $350 | O6: 606.87 | P6: 1304.77 | Q6: 1183.39 | R6: 1881.29
A7: ADP | B7: NATIONAL OA MC 500-80% | C7: ADP|NATIONAL OA MC 500-80% | D7: Aetna National OA Managed Choice - OON covered | E7: N | F7: 500 | G7: 1000 | H7: 3500 | I7: 7000 | J7: 0.8 | K7: $25 | L7: $50 | M7: $10 / $45 / $70 | N7: $350 | O7: 882.91 | P7: 1898.25 | Q7: 1721.67 | R7: 2737.01
A8: ADP | B8: NATIONAL OA MC 1000-80% | C8: ADP|NATIONAL OA MC 1000-80% | D8: Aetna National OA Managed Choice - OON covered | E8: N | F8: 1000 | G8: 2000 | H8: 4500 | I8: 9000 | J8: 0.8 | K8: $25 | L8: $50 | M8: $10 / $45 / $70 | N8: $500 | O8: 768.21 | P8: 1651.66 | Q8: 1498.01 | R8: 2381.46
A9: ADP | B9: OA EPO HDHP 3500-80% | C9: ADP|OA EPO HDHP 3500-80% | D9: Aetna OA EPO - no out-of-network | E9: Y | F9: 3500 | G9: 7000 | H9: 6350 | I9: 12700 | J9: 0.8 | K9: 20% ded | L9: 20% ded | M9: $10d / $45d / $70d | N9: ded + 20% | O9: 490.12 | P9: 1053.75 | Q9: 955.73 | R9: 1519.36
A10: ADP | B10: OA EPO 500-80% | C10: ADP|OA EPO 500-80% | D10: Aetna OA EPO - no out-of-network | E10: N | F10: 500 | G10: 1000 | H10: 3500 | I10: 7000 | J10: 0.8 | K10: $25 | L10: $50 | M10: $10 / $45 / $70 | N10: $350 | O10: 825.23 | P10: 1774.24 | Q10: 1609.19 | R10: 2558.21
A11: ADP | B11: OA EPO 1000-80% | C11: ADP|OA EPO 1000-80% | D11: Aetna OA EPO - no out-of-network | E11: N | F11: 1000 | G11: 2000 | H11: 4500 | I11: 9000 | J11: 0.8 | K11: $25 | L11: $50 | M11: $10 / $45 / $70 | N11: $500 | O11: 749.15 | P11: 1610.67 | Q11: 1460.84 | R11: 2322.36
A12: ADP | B12: OA EPO 1500-100% | C12: ADP|OA EPO 1500-100% | D12: Aetna OA EPO - no out-of-network | E12: N | F12: 1500 | G12: 3000 | H12: 5000 | I12: 10000 | J12: 1 | K12: $30 | L12: $60 | M12: $10 / $45 / $70 | N12: $500 | O12: 744.88 | P12: 1601.49 | Q12: 1452.51 | R12: 2309.12
A13: ADP | B13: OA EPO HDHP 6000-80% | C13: ADP|OA EPO HDHP 6000-80% | D13: Aetna OA EPO - no out-of-network | E13: Y | F13: 6000 | G13: 12000 | H13: 6500 | I13: 13000 | J13: 0.8 | K13: 20% ded | L13: 20% ded | M13: $10d / $45d / $70d | N13: ded + 20% | O13: 437.9 | P13: 941.49 | Q13: 853.91 | R13: 1357.49
A14: ADP | B14: OA EPO 3000-80% | C14: ADP|OA EPO 3000-80% | D14: Aetna OA EPO - no out-of-network | E14: N | F14: 3000 | G14: 6000 | H14: 7000 | I14: 14000 | J14: 0.8 | K14: $30 | L14: $60 | M14: $10 / $50 / $80 | N14: $500 | O14: 629.01 | P14: 1352.36 | Q14: 1226.56 | R14: 1949.92
A15: ADP | B15: OA EPO 8000-80% ValueINT | C15: ADP|OA EPO 8000-80% ValueINT | D15: Aetna OA EPO - no out-of-network | E15: N | F15: 8000 | G15: 16000 | H15: 10000 | I15: 20000 | J15: 0.8 | K15: $10 | L15: $110 | M15: $10 / $50d / $90d | N15: ded + 20% | O15: 374.03 | P15: 804.17 | Q15: 729.36 | R15: 1159.51
A16: TriNet | B16: Aetna ACO 6500 AZ | C16: TriNet|Aetna ACO 6500 AZ | D16: Banner Health Network | E16: N | F16: 6500 | G16: 13000 | H16: 7500 | I16: 15000 | J16: 1 | K16: $25 | L16: $65 | M16: $10 / $45 / $80 | N16: 0% ded | O16: 385 | P16: 889 | Q16: 785 | R16: 1166
... A34: Angle | B34: ANG TRAD 1000/2000 | C34: Angle|ANG TRAD 1000/2000 | D34: Cigna PPO (OON 50% after separate ded) | E34: N | F34: 1000 | G34: 2000 | H34: 2000 | I34: 4000 | J34: 0.8 | K34: $10 | L34: $30 | M34: $10 / $30 | N34: $200 | O34: 546.33 | P34: 1147.29 | Q34: 1038.02 | R34: 1693.61
A36: Every cell above is a hardcoded input transcribed from the vendor's own document. Sources: ADP TotalSource 2026 renewal deck pp.6-8; TriNet quote Q-00412887 strategy appendix pp.13-15; Angle Health / CapFi presentation quote 400798.
A37: Angle out-of-network: 50% coinsurance after a separate out-of-network deductible. ADP EPO plans have no out-of-network benefit at all except emergencies.

Sheet Cost by Tier
A1: What each plan costs Onyx and the employee, by tier
A2: One row per plan per tier. Onyx pays the greater of its tier target and the vendor's floor, never more than the premium. Worst case = the employee's annual premium plus the household out-of-pocket maximum.
A4: Vendor | B4: Plan | C4: Key | D4: Tier | E4: Code | F4: HSA | G4: Monthly premium | H4: Onyx tier target $/mo | I4: Vendor floor $/mo | J4: Onyx pays $/mo | K4: Employee pays $/mo | L4: Onyx pays $/yr | M4: Employee pays $/yr | N4: Onyx share of premium | O4: Deductible (this tier) | P4: OOP max (this tier) | Q4: Worst case to employee $/yr | R4: Row key
A5: ADP | B5: EPO HDHP 2000-100Copay TIF | C5: ADP|EPO HDHP 2000-100Copay TIF | D5: Employee only | E5: EE | F5: =INDEX('Plan Design'!$E$5:$E$34,MATCH($C5,'Plan Design'!$C$5:$C$34,0)) -> Y | G5: =INDEX('Plan Design'!$O$5:$R$34,MATCH($C5,'Plan Design'!$C$5:$C$34,0),MATCH($E5,'Plan Design'!$O$4:$R$4,0)) -> 640.66 | H5: =INDEX(Assumptions!$C$10:$C$13,MATCH($E5,Assumptions!$B$10:$B$13,0)) -> 300 | I5: =INDEX(Assumptions!$D$18:$D$20,MATCH($A5,Assumptions!$A$18:$A$20,0)) -> 187.015 | J5: =MIN($G5,MAX($H5,$I5)) -> 300 | K5: =$G5-$J5 -> 340.66 | L5: =$J5*12 -> 3600 | M5: =$K5*12 -> 4087.92 | N5: =IF($G5=0,0,$J5/$G5) -> 0.4682671 | O5: =IF($E5="EE",INDEX('Plan Design'!$F$5:$F$34,MATCH($C5,'Plan Design'!$C$5:$C$34,0)),INDEX('Plan Design'!$G$5:$G$34,MATCH($C5,'Plan Design'!$C$5:$C$34,0))) -> 2000 | P5: =IF($E5="EE",INDEX('Plan Design'!$H$5:$H$34,MATCH($C5,'Plan Design'!$C$5:$C$34,0)),INDEX('Plan Design'!$I$5:$I$34,MATCH($C5,'Plan Design'!$C$5:$C$34,0))) -> 3500 | Q5: =$M5+$P5 -> 7587.92 | R5: =$C5&"|"&$E5 -> ADP|EPO HDHP 2000-100Copay TIF|EE
A6: ADP | B6: EPO HDHP 2000-100Copay TIF | C6: ADP|EPO HDHP 2000-100Copay TIF | D6: Employee + spouse | E6: ES | F6: =INDEX('Plan Design'!$E$5:$E$34,MATCH($C6,'Plan Design'!$C$5:$C$34,0)) -> Y | G6: =INDEX('Plan Design'!$O$5:$R$34,MATCH($C6,'Plan Design'!$C$5:$C$34,0),MATCH($E6,'Plan Design'!$O$4:$R$4,0)) -> 1377.42 | H6: =INDEX(Assumptions!$C$10:$C$13,MATCH($E6,Assumptions!$B$10:$B$13,0)) -> 600 | I6: =INDEX(Assumptions!$D$18:$D$20,MATCH($A6,Assumptions!$A$18:$A$20,0)) -> 187.015 | J6: =MIN($G6,MAX($H6,$I6)) -> 600 | K6: =$G6-$J6 -> 777.42 | L6: =$J6*12 -> 7200 | M6: =$K6*12 -> 9329.04 | N6: =IF($G6=0,0,$J6/$G6) -> 0.43559699 | O6: =IF($E6="EE",INDEX('Plan Design'!$F$5:$F$34,MATCH($C6,'Plan Design'!$C$5:$C$34,0)),INDEX('Plan Design'!$G$5:$G$34,MATCH($C6,'Plan Design'!$C$5:$C$34,0))) -> 4000 | P6: =IF($E6="EE",INDEX('Plan Design'!$H$5:$H$34,MATCH($C6,'Plan Design'!$C$5:$C$34,0)),INDEX('Plan Design'!$I$5:$I$34,MATCH($C6,'Plan Design'!$C$5:$C$34,0))) -> 7000 | Q6: =$M6+$P6 -> 16329.04 | R6: =$C6&"|"&$E6 -> ADP|EPO HDHP 2000-100Copay TIF|ES
A7: ADP | B7: EPO HDHP 2000-100Copay TIF | C7: ADP|EPO HDHP 2000-100Copay TIF | D7: Employee + child(ren) | E7: EC | F7: =INDEX('Plan Design'!$E$5:$E$34,MATCH($C7,'Plan Design'!$C$5:$C$34,0)) -> Y | G7: =INDEX('Plan Design'!$O$5:$R$34,MATCH($C7,'Plan Design'!$C$5:$C$34,0),MATCH($E7,'Plan Design'!$O$4:$R$4,0)) -> 1249.28 | H7: =INDEX(Assumptions!$C$10:$C$13,MATCH($E7,Assumptions!$B$10:$B$13,0)) -> 600 | I7: =INDEX(Assumptions!$D$18:$D$20,MATCH($A7,Assumptions!$A$18:$A$20,0)) -> 187.015 | J7: =MIN($G7,MAX($H7,$I7)) -> 600 | K7: =$G7-$J7 -> 649.28 | L7: =$J7*12 -> 7200 | M7: =$K7*12 -> 7791.36 | N7: =IF($G7=0,0,$J7/$G7) -> 0.48027664 | O7: =IF($E7="EE",INDEX('Plan Design'!$F$5:$F$34,MATCH($C7,'Plan Design'!$C$5:$C$34,0)),INDEX('Plan Design'!$G$5:$G$34,MATCH($C7,'Plan Design'!$C$5:$C$34,0))) -> 4000 | P7: =IF($E7="EE",INDEX('Plan Design'!$H$5:$H$34,MATCH($C7,'Plan Design'!$C$5:$C$34,0)),INDEX('Plan Design'!$I$5:$I$34,MATCH($C7,'Plan Design'!$C$5:$C$34,0))) -> 7000 | Q7: =$M7+$P7 -> 14791.36 | R7: =$C7&"|"&$E7 -> ADP|EPO HDHP 2000-100Copay TIF|EC
A8: ADP | B8: EPO HDHP 2000-100Copay TIF | C8: ADP|EPO HDHP 2000-100Copay TIF | D8: Family | E8: FAM | F8: =INDEX('Plan Design'!$E$5:$E$34,MATCH($C8,'Plan Design'!$C$5:$C$34,0)) -> Y | G8: =INDEX('Plan Design'!$O$5:$R$34,MATCH($C8,'Plan Design'!$C$5:$C$34,0),MATCH($E8,'Plan Design'!$O$4:$R$4,0)) -> 1986.04 | H8: =INDEX(Assumptions!$C$10:$C$13,MATCH($E8,Assumptions!$B$10:$B$13,0)) -> 1000 | I8: =INDEX(Assumptions!$D$18:$D$20,MATCH($A8,Assumptions!$A$18:$A$20,0)) -> 187.015 | J8: =MIN($G8,MAX($H8,$I8)) -> 1000 | K8: =$G8-$J8 -> 986.04 | L8: =$J8*12 -> 12000 | M8: =$K8*12 -> 11832.48 | N8: =IF($G8=0,0,$J8/$G8) -> 0.50351453 | O8: =IF($E8="EE",INDEX('Plan Design'!$F$5:$F$34,MATCH($C8,'Plan Design'!$C$5:$C$34,0)),INDEX('Plan Design'!$G$5:$G$34,MATCH($C8,'Plan Design'!$C$5:$C$34,0))) -> 4000 | P8: =IF($E8="EE",INDEX('Plan Design'!$H$5:$H$34,MATCH($C8,'Plan Design'!$C$5:$C$34,0)),INDEX('Plan Design'!$I$5:$I$34,MATCH($C8,'Plan Design'!$C$5:$C$34,0))) -> 7000 | Q8: =$M8+$P8 -> 18832.48 | R8: =$C8&"|"&$E8 -> ADP|EPO HDHP 2000-100Copay TIF|FAM
A9: ADP | B9: EPO HDHP 2500-100Copay TIF | C9: ADP|EPO HDHP 2500-100Copay TIF | D9: Employee only | E9: EE | F9: =INDEX('Plan Design'!$E$5:$E$34,MATCH($C9,'Plan Design'!$C$5:$C$34,0)) -> Y | G9: =INDEX('Plan Design'!$O$5:$R$34,MATCH($C9,'Plan Design'!$C$5:$C$34,0),MATCH($E9,'Plan Design'!$O$4:$R$4,0)) -> 606.87 | H9: =INDEX(Assumptions!$C$10:$C$13,MATCH($E9,Assumptions!$B$10:$B$13,0)) -> 300 | I9: =INDEX(Assumptions!$D$18:$D$20,MATCH($A9,Assumptions!$A$18:$A$20,0)) -> 187.015 | J9: =MIN($G9,MAX($H9,$I9)) -> 300 | K9: =$G9-$J9 -> 306.87 | L9: =$J9*12 -> 3600 | M9: =$K9*12 -> 3682.44 | N9: =IF($G9=0,0,$J9/$G9) -> 0.49433981 | O9: =IF($E9="EE",INDEX('Plan Design'!$F$5:$F$34,MATCH($C9,'Plan Design'!$C$5:$C$34,0)),INDEX('Plan Design'!$G$5:$G$34,MATCH($C9,'Plan Design'!$C$5:$C$34,0))) -> 2500 | P9: =IF($E9="EE",INDEX('Plan Design'!$H$5:$H$34,MATCH($C9,'Plan Design'!$C$5:$C$34,0)),INDEX('Plan Design'!$I$5:$I$34,MATCH($C9,'Plan Design'!$C$5:$C$34,0))) -> 3500 | Q9: =$M9+$P9 -> 7182.44 | R9: =$C9&"|"&$E9 -> ADP|EPO HDHP 2500-100Copay TIF|EE
A10: ADP | B10: EPO HDHP 2500-100Copay TIF | C10: ADP|EPO HDHP 2500-100Copay TIF | D10: Employee + spouse | E10: ES | F10: =INDEX('Plan Design'!$E$5:$E$34,MATCH($C10,'Plan Design'!$C$5:$C$34,0)) -> Y | G10: =INDEX('Plan Design'!$O$5:$R$34,MATCH($C10,'Plan Design'!$C$5:$C$34,0),MATCH($E10,'Plan Design'!$O$4:$R$4,0)) -> 1304.77 | H10: =INDEX(Assumptions!$C$10:$C$13,MATCH($E10,Assumptions!$B$10:$B$13,0)) -> 600 | I10: =INDEX(Assumptions!$D$18:$D$20,MATCH($A10,Assumptions!$A$18:$A$20,0)) -> 187.015 | J10: =MIN($G10,MAX($H10,$I10)) -> 600 | K10: =$G10-$J10 -> 704.77 | L10: =$J10*12 -> 7200 | M10: =$K10*12 -> 8457.24 | N10: =IF($G10=0,0,$J10/$G10) -> 0.45985116 | O10: =IF($E10="EE",INDEX('Plan Design'!$F$5:$F$34,MATCH($C10,'Plan Design'!$C$5:$C$34,0)),INDEX('Plan Design'!$G$5:$G$34,MATCH($C10,'Plan Design'!$C$5:$C$34,0))) -> 5000 | P10: =IF($E10="EE",INDEX('Plan Design'!$H$5:$H$34,MATCH($C10,'Plan Design'!$C$5:$C$34,0)),INDEX('Plan Design'!$I$5:$I$34,MATCH($C10,'Plan Design'!$C$5:$C$34,0))) -> 7000 | Q10: =$M10+$P10 -> 15457.24 | R10: =$C10&"|"&$E10 -> ADP|EPO HDHP 2500-100Copay TIF|ES
A11: ADP | B11: EPO HDHP 2500-100Copay TIF | C11: ADP|EPO HDHP 2500-100Copay TIF | D11: Employee + child(ren) | E11: EC | F11: =INDEX('Plan Design'!$E$5:$E$34,MATCH($C11,'Plan Design'!$C$5:$C$34,0)) -> Y | G11: =INDEX('Plan Design'!$O$5:$R$34,MATCH($C11,'Plan Design'!$C$5:$C$34,0),MATCH($E11,'Plan Design'!$O$4:$R$4,0)) -> 1183.39 | H11: =INDEX(Assumptions!$C$10:$C$13,MATCH($E11,Assumptions!$B$10:$B$13,0)) -> 600 | I11: =INDEX(Assumptions!$D$18:$D$20,MATCH($A11,Assumptions!$A$18:$A$20,0)) -> 187.015 | J11: =MIN($G11,MAX($H11,$I11)) -> 600 | K11: =$G11-$J11 -> 583.39 | L11: =$J11*12 -> 7200 | M11: =$K11*12 -> 7000.68 | N11: =IF($G11=0,0,$J11/$G11) -> 0.50701797 | O11: =IF($E11="EE",INDEX('Plan Design'!$F$5:$F$34,MATCH($C11,'Plan Design'!$C$5:$C$34,0)),INDEX('Plan Design'!$G$5:$G$34,MATCH($C11,'Plan Design'!$C$5:$C$34,0))) -> 5000 | P11: =IF($E11="EE",INDEX('Plan Design'!$H$5:$H$34,MATCH($C11,'Plan Design'!$C$5:$C$34,0)),INDEX('Plan Design'!$I$5:$I$34,MATCH($C11,'Plan Design'!$C$5:$C$34,0))) -> 7000 | Q11: =$M11+$P11 -> 14000.68 | R11: =$C11&"|"&$E11 -> ADP|EPO HDHP 2500-100Copay TIF|EC
A12: ADP | B12: EPO HDHP 2500-100Copay TIF | C12: ADP|EPO HDHP 2500-100Copay TIF | D12: Family | E12: FAM | F12: =INDEX('Plan Design'!$E$5:$E$34,MATCH($C12,'Plan Design'!$C$5:$C$34,0)) -> Y | G12: =INDEX('Plan Design'!$O$5:$R$34,MATCH($C12,'Plan Design'!$C$5:$C$34,0),MATCH($E12,'Plan Design'!$O$4:$R$4,0)) -> 1881.29 | H12: =INDEX(Assumptions!$C$10:$C$13,MATCH($E12,Assumptions!$B$10:$B$13,0)) -> 1000 | I12: =INDEX(Assumptions!$D$18:$D$20,MATCH($A12,Assumptions!$A$18:$A$20,0)) -> 187.015 | J12: =MIN($G12,MAX($H12,$I12)) -> 1000 | K12: =$G12-$J12 -> 881.29 | L12: =$J12*12 -> 12000 | M12: =$K12*12 -> 10575.48 | N12: =IF($G12=0,0,$J12/$G12) -> 0.53155016 | O12: =IF($E12="EE",INDEX('Plan Design'!$F$5:$F$34,MATCH($C12,'Plan Design'!$C$5:$C$34,0)),INDEX('Plan Design'!$G$5:$G$34,MATCH($C12,'Plan Design'!$C$5:$C$34,0))) -> 5000 | P12: =IF($E12="EE",INDEX('Plan Design'!$H$5:$H$34,MATCH($C12,'Plan Design'!$C$5:$C$34,0)),INDEX('Plan Design'!$I$5:$I$34,MATCH($C12,'Plan Design'!$C$5:$C$34,0))) -> 7000 | Q12: =$M12+$P12 -> 17575.48 | R12: =$C12&"|"&$E12 -> ADP|EPO HDHP 2500-100Copay TIF|FAM
A13: ADP | B13: NATIONAL OA MC 500-80% | C13: ADP|NATIONAL OA MC 500-80% | D13: Employee only | E13: EE | F13: =INDEX('Plan Design'!$E$5:$E$34,MATCH($C13,'Plan Design'!$C$5:$C$34,0)) -> N | G13: =INDEX('Plan Design'!$O$5:$R$34,MATCH($C13,'Plan Design'!$C$5:$C$34,0),MATCH($E13,'Plan Design'!$O$4:$R$4,0)) -> 882.91 | H13: =INDEX(Assumptions!$C$10:$C$13,MATCH($E13,Assumptions!$B$10:$B$13,0)) -> 300 | I13: =INDEX(Assumptions!$D$18:$D$20,MATCH($A13,Assumptions!$A$18:$A$20,0)) -> 187.015 | J13: =MIN($G13,MAX($H13,$I13)) -> 300 | K13: =$G13-$J13 -> 582.91 | L13: =$J13*12 -> 3600 | M13: =$K13*12 -> 6994.92 | N13: =IF($G13=0,0,$J13/$G13) -> 0.33978548 | O13: =IF($E13="EE",INDEX('Plan Design'!$F$5:$F$34,MATCH($C13,'Plan Design'!$C$5:$C$34,0)),INDEX('Plan Design'!$G$5:$G$34,MATCH($C13,'Plan Design'!$C$5:$C$34,0))) -> 500 | P13: =IF($E13="EE",INDEX('Plan Design'!$H$5:$H$34,MATCH($C13,'Plan Design'!$C$5:$C$34,0)),INDEX('Plan Design'!$I$5:$I$34,MATCH($C13,'Plan Design'!$C$5:$C$34,0))) -> 3500 | Q13: =$M13+$P13 -> 10494.92 | R13: =$C13&"|"&$E13 -> ADP|NATIONAL OA MC 500-80%|EE
A14: ADP | B14: NATIONAL OA MC 500-80% | C14: ADP|NATIONAL OA MC 500-80% | D14: Employee + spouse | E14: ES | F14: =INDEX('Plan Design'!$E$5:$E$34,MATCH($C14,'Plan Design'!$C$5:$C$34,0)) -> N | G14: =INDEX('Plan Design'!$O$5:$R$34,MATCH($C14,'Plan Design'!$C$5:$C$34,0),MATCH($E14,'Plan Design'!$O$4:$R$4,0)) -> 1898.25 | H14: =INDEX(Assumptions!$C$10:$C$13,MATCH($E14,Assumptions!$B$10:$B$13,0)) -> 600 | I14: =INDEX(Assumptions!$D$18:$D$20,MATCH($A14,Assumptions!$A$18:$A$20,0)) -> 187.015 | J14: =MIN($G14,MAX($H14,$I14)) -> 600 | K14: =$G14-$J14 -> 1298.25 | L14: =$J14*12 -> 7200 | M14: =$K14*12 -> 15579 | N14: =IF($G14=0,0,$J14/$G14) -> 0.3160806 | O14: =IF($E14="EE",INDEX('Plan Design'!$F$5:$F$34,MATCH($C14,'Plan Design'!$C$5:$C$34,0)),INDEX('Plan Design'!$G$5:$G$34,MATCH($C14,'Plan Design'!$C$5:$C$34,0))) -> 1000 | P14: =IF($E14="EE",INDEX('Plan Design'!$H$5:$H$34,MATCH($C14,'Plan Design'!$C$5:$C$34,0)),INDEX('Plan Design'!$I$5:$I$34,MATCH($C14,'Plan Design'!$C$5:$C$34,0))) -> 7000 | Q14: =$M14+$P14 -> 22579 | R14: =$C14&"|"&$E14 -> ADP|NATIONAL OA MC 500-80%|ES
A15: ADP | B15: NATIONAL OA MC 500-80% | C15: ADP|NATIONAL OA MC 500-80% | D15: Employee + child(ren) | E15: EC | F15: =INDEX('Plan Design'!$E$5:$E$34,MATCH($C15,'Plan Design'!$C$5:$C$34,0)) -> N | G15: =INDEX('Plan Design'!$O$5:$R$34,MATCH($C15,'Plan Design'!$C$5:$C$34,0),MATCH($E15,'Plan Design'!$O$4:$R$4,0)) -> 1721.67 | H15: =INDEX(Assumptions!$C$10:$C$13,MATCH($E15,Assumptions!$B$10:$B$13,0)) -> 600 | I15: =INDEX(Assumptions!$D$18:$D$20,MATCH($A15,Assumptions!$A$18:$A$20,0)) -> 187.015 | J15: =MIN($G15,MAX($H15,$I15)) -> 600 | K15: =$G15-$J15 -> 1121.67 | L15: =$J15*12 -> 7200 | M15: =$K15*12 -> 13460.04 | N15: =IF($G15=0,0,$J15/$G15) -> 0.34849884 | O15: =IF($E15="EE",INDEX('Plan Design'!$F$5:$F$34,MATCH($C15,'Plan Design'!$C$5:$C$34,0)),INDEX('Plan Design'!$G$5:$G$34,MATCH($C15,'Plan Design'!$C$5:$C$34,0))) -> 1000 | P15: =IF($E15="EE",INDEX('Plan Design'!$H$5:$H$34,MATCH($C15,'Plan Design'!$C$5:$C$34,0)),INDEX('Plan Design'!$I$5:$I$34,MATCH($C15,'Plan Design'!$C$5:$C$34,0))) -> 7000 | Q15: =$M15+$P15 -> 20460.04 | R15: =$C15&"|"&$E15 -> ADP|NATIONAL OA MC 500-80%|EC
A16: ADP | B16: NATIONAL OA MC 500-80% | C16: ADP|NATIONAL OA MC 500-80% | D16: Family | E16: FAM | F16: =INDEX('Plan Design'!$E$5:$E$34,MATCH($C16,'Plan Design'!$C$5:$C$34,0)) -> N | G16: =INDEX('Plan Design'!$O$5:$R$34,MATCH($C16,'Plan Design'!$C$5:$C$34,0),MATCH($E16,'Plan Design'!$O$4:$R$4,0)) -> 2737.01 | H16: =INDEX(Assumptions!$C$10:$C$13,MATCH($E16,Assumptions!$B$10:$B$13,0)) -> 1000 | I16: =INDEX(Assumptions!$D$18:$D$20,MATCH($A16,Assumptions!$A$18:$A$20,0)) -> 187.015 | J16: =MIN($G16,MAX($H16,$I16)) -> 1000 | K16: =$G16-$J16 -> 1737.01 | L16: =$J16*12 -> 12000 | M16: =$K16*12 -> 20844.12 | N16: =IF($G16=0,0,$J16/$G16) -> 0.3653622 | O16: =IF($E16="EE",INDEX('Plan Design'!$F$5:$F$34,MATCH($C16,'Plan Design'!$C$5:$C$34,0)),INDEX('Plan Design'!$G$5:$G$34,MATCH($C16,'Plan Design'!$C$5:$C$34,0))) -> 1000 | P16: =IF($E16="EE",INDEX('Plan Design'!$H$5:$H$34,MATCH($C16,'Plan Design'!$C$5:$C$34,0)),INDEX('Plan Design'!$I$5:$I$34,MATCH($C16,'Plan Design'!$C$5:$C$34,0))) -> 7000 | Q16: =$M16+$P16 -> 27844.12 | R16: =$C16&"|"&$E16 -> ADP|NATIONAL OA MC 500-80%|FAM
... A124: Angle | B124: ANG TRAD 1000/2000 | C124: Angle|ANG TRAD 1000/2000 | D124: Family | E124: FAM | F124: =INDEX('Plan Design'!$E$5:$E$34,MATCH($C124,'Plan Design'!$C$5:$C$34,0)) -> N | G124: =INDEX('Plan Design'!$O$5:$R$34,MATCH($C124,'Plan Design'!$C$5:$C$34,0),MATCH($E124,'Plan Design'!$O$4:$R$4,0)) -> 1693.61 | H124: =INDEX(Assumptions!$C$10:$C$13,MATCH($E124,Assumptions!$B$10:$B$13,0)) -> 1000 | I124: =INDEX(Assumptions!$D$18:$D$20,MATCH($A124,Assumptions!$A$18:$A$20,0)) -> 219.515 | J124: =MIN($G124,MAX($H124,$I124)) -> 1000 | K124: =$G124-$J124 -> 693.61 | L124: =$J124*12 -> 12000 | M124: =$K124*12 -> 8323.32 | N124: =IF($G124=0,0,$J124/$G124) -> 0.59045471 | O124: =IF($E124="EE",INDEX('Plan Design'!$F$5:$F$34,MATCH($C124,'Plan Design'!$C$5:$C$34,0)),INDEX('Plan Design'!$G$5:$G$34,MATCH($C124,'Plan Design'!$C$5:$C$34,0))) -> 2000 | P124: =IF($E124="EE",INDEX('Plan Design'!$H$5:$H$34,MATCH($C124,'Plan Design'!$C$5:$C$34,0)),INDEX('Plan Design'!$I$5:$I$34,MATCH($C124,'Plan Design'!$C$5:$C$34,0))) -> 4000 | Q124: =$M124+$P124 -> 12323.32 | R124: =$C124&"|"&$E124 -> Angle|ANG TRAD 1000/2000|FAM
A126: Worst case is the true ceiling for that household in one plan year: it assumes the family hits the in-network out-of-pocket maximum in full. It does not include out-of-network care, balance billing, or anything the plan excludes.
A127: HSA funding is not modeled. On an HSA-eligible plan an employee can pay part of that worst case with pretax dollars, so the real cost is lower - but by an amount only the employee controls.

Sheet Onyx Total Cost
A1: Total cost at Onyx's actual enrollment, one plan at a time
A2: Assumes all four enrollees take the same plan: Steven family, Jessica family, Lisa employee only, Christine employee + spouse. Combined worst case assumes every household hits its out-of-pocket maximum in the same year - a ceiling, not a forecast.
A4: Vendor | B4: Plan | C4: Key | D4: HSA | E4: Onyx $/mo | F4: Onyx $/yr | G4: Employees $/mo (all 4) | H4: Employees $/yr (all 4) | I4: Onyx + employees $/yr | J4: Combined worst case $/yr | K4: Onyx variance vs $34,800 target
A5: ADP | B5: EPO HDHP 2000-100Copay TIF | C5: ADP|EPO HDHP 2000-100Copay TIF | D5: =INDEX('Plan Design'!$E$5:$E$34,MATCH($C5,'Plan Design'!$C$5:$C$34,0)) -> Y | E5: =SUMIFS('Cost by Tier'!$J$5:$J$124,'Cost by Tier'!$C$5:$C$124,$C5,'Cost by Tier'!$E$5:$E$124,"EE")+SUMIFS('Cost by Tier'!$J$5:$J$124,'Cost by Tier'!$C$5:$C$124,$C5,'Cost by Tier'!$E$5:$E$124,"ES")+2*SUMIFS('Cost by Tier'!$J$5:$J$124,'Cost by Tier'!$C$5:$C$124,$C5,'Cost by Tier'!$E$5:$E$124,"FAM") -> 2900 | F5: =E5*12 -> 34800 | G5: =SUMIFS('Cost by Tier'!$K$5:$K$124,'Cost by Tier'!$C$5:$C$124,$C5,'Cost by Tier'!$E$5:$E$124,"EE")+SUMIFS('Cost by Tier'!$K$5:$K$124,'Cost by Tier'!$C$5:$C$124,$C5,'Cost by Tier'!$E$5:$E$124,"ES")+2*SUMIFS('Cost by Tier'!$K$5:$K$124,'Cost by Tier'!$C$5:$C$124,$C5,'Cost by Tier'!$E$5:$E$124,"FAM") -> 3090.16 | H5: =G5*12 -> 37081.92 | I5: =F5+H5 -> 71881.92 | J5: =SUMIFS('Cost by Tier'!$Q$5:$Q$124,'Cost by Tier'!$C$5:$C$124,$C5,'Cost by Tier'!$E$5:$E$124,"EE")+SUMIFS('Cost by Tier'!$Q$5:$Q$124,'Cost by Tier'!$C$5:$C$124,$C5,'Cost by Tier'!$E$5:$E$124,"ES")+2*SUMIFS('Cost by Tier'!$Q$5:$Q$124,'Cost by Tier'!$C$5:$C$124,$C5,'Cost by Tier'!$E$5:$E$124,"FAM") -> 61581.92 | K5: =F5-Assumptions!$D$14 -> 0
A6: ADP | B6: EPO HDHP 2500-100Copay TIF | C6: ADP|EPO HDHP 2500-100Copay TIF | D6: =INDEX('Plan Design'!$E$5:$E$34,MATCH($C6,'Plan Design'!$C$5:$C$34,0)) -> Y | E6: =SUMIFS('Cost by Tier'!$J$5:$J$124,'Cost by Tier'!$C$5:$C$124,$C6,'Cost by Tier'!$E$5:$E$124,"EE")+SUMIFS('Cost by Tier'!$J$5:$J$124,'Cost by Tier'!$C$5:$C$124,$C6,'Cost by Tier'!$E$5:$E$124,"ES")+2*SUMIFS('Cost by Tier'!$J$5:$J$124,'Cost by Tier'!$C$5:$C$124,$C6,'Cost by Tier'!$E$5:$E$124,"FAM") -> 2900 | F6: =E6*12 -> 34800 | G6: =SUMIFS('Cost by Tier'!$K$5:$K$124,'Cost by Tier'!$C$5:$C$124,$C6,'Cost by Tier'!$E$5:$E$124,"EE")+SUMIFS('Cost by Tier'!$K$5:$K$124,'Cost by Tier'!$C$5:$C$124,$C6,'Cost by Tier'!$E$5:$E$124,"ES")+2*SUMIFS('Cost by Tier'!$K$5:$K$124,'Cost by Tier'!$C$5:$C$124,$C6,'Cost by Tier'!$E$5:$E$124,"FAM") -> 2774.22 | H6: =G6*12 -> 33290.64 | I6: =F6+H6 -> 68090.64 | J6: =SUMIFS('Cost by Tier'!$Q$5:$Q$124,'Cost by Tier'!$C$5:$C$124,$C6,'Cost by Tier'!$E$5:$E$124,"EE")+SUMIFS('Cost by Tier'!$Q$5:$Q$124,'Cost by Tier'!$C$5:$C$124,$C6,'Cost by Tier'!$E$5:$E$124,"ES")+2*SUMIFS('Cost by Tier'!$Q$5:$Q$124,'Cost by Tier'!$C$5:$C$124,$C6,'Cost by Tier'!$E$5:$E$124,"FAM") -> 57790.64 | K6: =F6-Assumptions!$D$14 -> 0
A7: ADP | B7: NATIONAL OA MC 500-80% | C7: ADP|NATIONAL OA MC 500-80% | D7: =INDEX('Plan Design'!$E$5:$E$34,MATCH($C7,'Plan Design'!$C$5:$C$34,0)) -> N | E7: =SUMIFS('Cost by Tier'!$J$5:$J$124,'Cost by Tier'!$C$5:$C$124,$C7,'Cost by Tier'!$E$5:$E$124,"EE")+SUMIFS('Cost by Tier'!$J$5:$J$124,'Cost by Tier'!$C$5:$C$124,$C7,'Cost by Tier'!$E$5:$E$124,"ES")+2*SUMIFS('Cost by Tier'!$J$5:$J$124,'Cost by Tier'!$C$5:$C$124,$C7,'Cost by Tier'!$E$5:$E$124,"FAM") -> 2900 | F7: =E7*12 -> 34800 | G7: =SUMIFS('Cost by Tier'!$K$5:$K$124,'Cost by Tier'!$C$5:$C$124,$C7,'Cost by Tier'!$E$5:$E$124,"EE")+SUMIFS('Cost by Tier'!$K$5:$K$124,'Cost by Tier'!$C$5:$C$124,$C7,'Cost by Tier'!$E$5:$E$124,"ES")+2*SUMIFS('Cost by Tier'!$K$5:$K$124,'Cost by Tier'!$C$5:$C$124,$C7,'Cost by Tier'!$E$5:$E$124,"FAM") -> 5355.18 | H7: =G7*12 -> 64262.16 | I7: =F7+H7 -> 99062.16 | J7: =SUMIFS('Cost by Tier'!$Q$5:$Q$124,'Cost by Tier'!$C$5:$C$124,$C7,'Cost by Tier'!$E$5:$E$124,"EE")+SUMIFS('Cost by Tier'!$Q$5:$Q$124,'Cost by Tier'!$C$5:$C$124,$C7,'Cost by Tier'!$E$5:$E$124,"ES")+2*SUMIFS('Cost by Tier'!$Q$5:$Q$124,'Cost by Tier'!$C$5:$C$124,$C7,'Cost by Tier'!$E$5:$E$124,"FAM") -> 88762.16 | K7: =F7-Assumptions!$D$14 -> 0
A8: ADP | B8: NATIONAL OA MC 1000-80% | C8: ADP|NATIONAL OA MC 1000-80% | D8: =INDEX('Plan Design'!$E$5:$E$34,MATCH($C8,'Plan Design'!$C$5:$C$34,0)) -> N | E8: =SUMIFS('Cost by Tier'!$J$5:$J$124,'Cost by Tier'!$C$5:$C$124,$C8,'Cost by Tier'!$E$5:$E$124,"EE")+SUMIFS('Cost by Tier'!$J$5:$J$124,'Cost by Tier'!$C$5:$C$124,$C8,'Cost by Tier'!$E$5:$E$124,"ES")+2*SUMIFS('Cost by Tier'!$J$5:$J$124,'Cost by Tier'!$C$5:$C$124,$C8,'Cost by Tier'!$E$5:$E$124,"FAM") -> 2900 | F8: =E8*12 -> 34800 | G8: =SUMIFS('Cost by Tier'!$K$5:$K$124,'Cost by Tier'!$C$5:$C$124,$C8,'Cost by Tier'!$E$5:$E$124,"EE")+SUMIFS('Cost by Tier'!$K$5:$K$124,'Cost by Tier'!$C$5:$C$124,$C8,'Cost by Tier'!$E$5:$E$124,"ES")+2*SUMIFS('Cost by Tier'!$K$5:$K$124,'Cost by Tier'!$C$5:$C$124,$C8,'Cost by Tier'!$E$5:$E$124,"FAM") -> 4282.79 | H8: =G8*12 -> 51393.48 | I8: =F8+H8 -> 86193.48 | J8: =SUMIFS('Cost by Tier'!$Q$5:$Q$124,'Cost by Tier'!$C$5:$C$124,$C8,'Cost by Tier'!$E$5:$E$124,"EE")+SUMIFS('Cost by Tier'!$Q$5:$Q$124,'Cost by Tier'!$C$5:$C$124,$C8,'Cost by Tier'!$E$5:$E$124,"ES")+2*SUMIFS('Cost by Tier'!$Q$5:$Q$124,'Cost by Tier'!$C$5:$C$124,$C8,'Cost by Tier'!$E$5:$E$124,"FAM") -> 82893.48 | K8: =F8-Assumptions!$D$14 -> 0
A9: ADP | B9: OA EPO HDHP 3500-80% | C9: ADP|OA EPO HDHP 3500-80% | D9: =INDEX('Plan Design'!$E$5:$E$34,MATCH($C9,'Plan Design'!$C$5:$C$34,0)) -> Y | E9: =SUMIFS('Cost by Tier'!$J$5:$J$124,'Cost by Tier'!$C$5:$C$124,$C9,'Cost by Tier'!$E$5:$E$124,"EE")+SUMIFS('Cost by Tier'!$J$5:$J$124,'Cost by Tier'!$C$5:$C$124,$C9,'Cost by Tier'!$E$5:$E$124,"ES")+2*SUMIFS('Cost by Tier'!$J$5:$J$124,'Cost by Tier'!$C$5:$C$124,$C9,'Cost by Tier'!$E$5:$E$124,"FAM") -> 2900 | F9: =E9*12 -> 34800 | G9: =SUMIFS('Cost by Tier'!$K$5:$K$124,'Cost by Tier'!$C$5:$C$124,$C9,'Cost by Tier'!$E$5:$E$124,"EE")+SUMIFS('Cost by Tier'!$K$5:$K$124,'Cost by Tier'!$C$5:$C$124,$C9,'Cost by Tier'!$E$5:$E$124,"ES")+2*SUMIFS('Cost by Tier'!$K$5:$K$124,'Cost by Tier'!$C$5:$C$124,$C9,'Cost by Tier'!$E$5:$E$124,"FAM") -> 1682.59 | H9: =G9*12 -> 20191.08 | I9: =F9+H9 -> 54991.08 | J9: =SUMIFS('Cost by Tier'!$Q$5:$Q$124,'Cost by Tier'!$C$5:$C$124,$C9,'Cost by Tier'!$E$5:$E$124,"EE")+SUMIFS('Cost by Tier'!$Q$5:$Q$124,'Cost by Tier'!$C$5:$C$124,$C9,'Cost by Tier'!$E$5:$E$124,"ES")+2*SUMIFS('Cost by Tier'!$Q$5:$Q$124,'Cost by Tier'!$C$5:$C$124,$C9,'Cost by Tier'!$E$5:$E$124,"FAM") -> 64641.08 | K9: =F9-Assumptions!$D$14 -> 0
A10: ADP | B10: OA EPO 500-80% | C10: ADP|OA EPO 500-80% | D10: =INDEX('Plan Design'!$E$5:$E$34,MATCH($C10,'Plan Design'!$C$5:$C$34,0)) -> N | E10: =SUMIFS('Cost by Tier'!$J$5:$J$124,'Cost by Tier'!$C$5:$C$124,$C10,'Cost by Tier'!$E$5:$E$124,"EE")+SUMIFS('Cost by Tier'!$J$5:$J$124,'Cost by Tier'!$C$5:$C$124,$C10,'Cost by Tier'!$E$5:$E$124,"ES")+2*SUMIFS('Cost by Tier'!$J$5:$J$124,'Cost by Tier'!$C$5:$C$124,$C10,'Cost by Tier'!$E$5:$E$124,"FAM") -> 2900 | F10: =E10*12 -> 34800 | G10: =SUMIFS('Cost by Tier'!$K$5:$K$124,'Cost by Tier'!$C$5:$C$124,$C10,'Cost by Tier'!$E$5:$E$124,"EE")+SUMIFS('Cost by Tier'!$K$5:$K$124,'Cost by Tier'!$C$5:$C$124,$C10,'Cost by Tier'!$E$5:$E$124,"ES")+2*SUMIFS('Cost by Tier'!$K$5:$K$124,'Cost by Tier'!$C$5:$C$124,$C10,'Cost by Tier'!$E$5:$E$124,"FAM") -> 4815.89 | H10: =G10*12 -> 57790.68 | I10: =F10+H10 -> 92590.68 | J10: =SUMIFS('Cost by Tier'!$Q$5:$Q$124,'Cost by Tier'!$C$5:$C$124,$C10,'Cost by Tier'!$E$5:$E$124,"EE")+SUMIFS('Cost by Tier'!$Q$5:$Q$124,'Cost by Tier'!$C$5:$C$124,$C10,'Cost by Tier'!$E$5:$E$124,"ES")+2*SUMIFS('Cost by Tier'!$Q$5:$Q$124,'Cost by Tier'!$C$5:$C$124,$C10,'Cost by Tier'!$E$5:$E$124,"FAM") -> 82290.68 | K10: =F10-Assumptions!$D$14 -> 0
A11: ADP | B11: OA EPO 1000-80% | C11: ADP|OA EPO 1000-80% | D11: =INDEX('Plan Design'!$E$5:$E$34,MATCH($C11,'Plan Design'!$C$5:$C$34,0)) -> N | E11: =SUMIFS('Cost by Tier'!$J$5:$J$124,'Cost by Tier'!$C$5:$C$124,$C11,'Cost by Tier'!$E$5:$E$124,"EE")+SUMIFS('Cost by Tier'!$J$5:$J$124,'Cost by Tier'!$C$5:$C$124,$C11,'Cost by Tier'!$E$5:$E$124,"ES")+2*SUMIFS('Cost by Tier'!$J$5:$J$124,'Cost by Tier'!$C$5:$C$124,$C11,'Cost by Tier'!$E$5:$E$124,"FAM") -> 2900 | F11: =E11*12 -> 34800 | G11: =SUMIFS('Cost by Tier'!$K$5:$K$124,'Cost by Tier'!$C$5:$C$124,$C11,'Cost by Tier'!$E$5:$E$124,"EE")+SUMIFS('Cost by Tier'!$K$5:$K$124,'Cost by Tier'!$C$5:$C$124,$C11,'Cost by Tier'!$E$5:$E$124,"ES")+2*SUMIFS('Cost by Tier'!$K$5:$K$124,'Cost by Tier'!$C$5:$C$124,$C11,'Cost by Tier'!$E$5:$E$124,"FAM") -> 4104.54 | H11: =G11*12 -> 49254.48 | I11: =F11+H11 -> 84054.48 | J11: =SUMIFS('Cost by Tier'!$Q$5:$Q$124,'Cost by Tier'!$C$5:$C$124,$C11,'Cost by Tier'!$E$5:$E$124,"EE")+SUMIFS('Cost by Tier'!$Q$5:$Q$124,'Cost by Tier'!$C$5:$C$124,$C11,'Cost by Tier'!$E$5:$E$124,"ES")+2*SUMIFS('Cost by Tier'!$Q$5:$Q$124,'Cost by Tier'!$C$5:$C$124,$C11,'Cost by Tier'!$E$5:$E$124,"FAM") -> 80754.48 | K11: =F11-Assumptions!$D$14 -> 0
A12: ADP | B12: OA EPO 1500-100% | C12: ADP|OA EPO 1500-100% | D12: =INDEX('Plan Design'!$E$5:$E$34,MATCH($C12,'Plan Design'!$C$5:$C$34,0)) -> N | E12: =SUMIFS('Cost by Tier'!$J$5:$J$124,'Cost by Tier'!$C$5:$C$124,$C12,'Cost by Tier'!$E$5:$E$124,"EE")+SUMIFS('Cost by Tier'!$J$5:$J$124,'Cost by Tier'!$C$5:$C$124,$C12,'Cost by Tier'!$E$5:$E$124,"ES")+2*SUMIFS('Cost by Tier'!$J$5:$J$124,'Cost by Tier'!$C$5:$C$124,$C12,'Cost by Tier'!$E$5:$E$124,"FAM") -> 2900 | F12: =E12*12 -> 34800 | G12: =SUMIFS('Cost by Tier'!$K$5:$K$124,'Cost by Tier'!$C$5:$C$124,$C12,'Cost by Tier'!$E$5:$E$124,"EE")+SUMIFS('Cost by Tier'!$K$5:$K$124,'Cost by Tier'!$C$5:$C$124,$C12,'Cost by Tier'!$E$5:$E$124,"ES")+2*SUMIFS('Cost by Tier'!$K$5:$K$124,'Cost by Tier'!$C$5:$C$124,$C12,'Cost by Tier'!$E$5:$E$124,"FAM") -> 4064.61 | H12: =G12*12 -> 48775.32 | I12: =F12+H12 -> 83575.32 | J12: =SUMIFS('Cost by Tier'!$Q$5:$Q$124,'Cost by Tier'!$C$5:$C$124,$C12,'Cost by Tier'!$E$5:$E$124,"EE")+SUMIFS('Cost by Tier'!$Q$5:$Q$124,'Cost by Tier'!$C$5:$C$124,$C12,'Cost by Tier'!$E$5:$E$124,"ES")+2*SUMIFS('Cost by Tier'!$Q$5:$Q$124,'Cost by Tier'!$C$5:$C$124,$C12,'Cost by Tier'!$E$5:$E$124,"FAM") -> 83775.32 | K12: =F12-Assumptions!$D$14 -> 0
A13: ADP | B13: OA EPO HDHP 6000-80% | C13: ADP|OA EPO HDHP 6000-80% | D13: =INDEX('Plan Design'!$E$5:$E$34,MATCH($C13,'Plan Design'!$C$5:$C$34,0)) -> Y | E13: =SUMIFS('Cost by Tier'!$J$5:$J$124,'Cost by Tier'!$C$5:$C$124,$C13,'Cost by Tier'!$E$5:$E$124,"EE")+SUMIFS('Cost by Tier'!$J$5:$J$124,'Cost by Tier'!$C$5:$C$124,$C13,'Cost by Tier'!$E$5:$E$124,"ES")+2*SUMIFS('Cost by Tier'!$J$5:$J$124,'Cost by Tier'!$C$5:$C$124,$C13,'Cost by Tier'!$E$5:$E$124,"FAM") -> 2900 | F13: =E13*12 -> 34800 | G13: =SUMIFS('Cost by Tier'!$K$5:$K$124,'Cost by Tier'!$C$5:$C$124,$C13,'Cost by Tier'!$E$5:$E$124,"EE")+SUMIFS('Cost by Tier'!$K$5:$K$124,'Cost by Tier'!$C$5:$C$124,$C13,'Cost by Tier'!$E$5:$E$124,"ES")+2*SUMIFS('Cost by Tier'!$K$5:$K$124,'Cost by Tier'!$C$5:$C$124,$C13,'Cost by Tier'!$E$5:$E$124,"FAM") -> 1194.37 | H13: =G13*12 -> 14332.44 | I13: =F13+H13 -> 49132.44 | J13: =SUMIFS('Cost by Tier'!$Q$5:$Q$124,'Cost by Tier'!$C$5:$C$124,$C13,'Cost by Tier'!$E$5:$E$124,"EE")+SUMIFS('Cost by Tier'!$Q$5:$Q$124,'Cost by Tier'!$C$5:$C$124,$C13,'Cost by Tier'!$E$5:$E$124,"ES")+2*SUMIFS('Cost by Tier'!$Q$5:$Q$124,'Cost by Tier'!$C$5:$C$124,$C13,'Cost by Tier'!$E$5:$E$124,"FAM") -> 59832.44 | K13: =F13-Assumptions!$D$14 -> 0
A14: ADP | B14: OA EPO 3000-80% | C14: ADP|OA EPO 3000-80% | D14: =INDEX('Plan Design'!$E$5:$E$34,MATCH($C14,'Plan Design'!$C$5:$C$34,0)) -> N | E14: =SUMIFS('Cost by Tier'!$J$5:$J$124,'Cost by Tier'!$C$5:$C$124,$C14,'Cost by Tier'!$E$5:$E$124,"EE")+SUMIFS('Cost by Tier'!$J$5:$J$124,'Cost by Tier'!$C$5:$C$124,$C14,'Cost by Tier'!$E$5:$E$124,"ES")+2*SUMIFS('Cost by Tier'!$J$5:$J$124,'Cost by Tier'!$C$5:$C$124,$C14,'Cost by Tier'!$E$5:$E$124,"FAM") -> 2900 | F14: =E14*12 -> 34800 | G14: =SUMIFS('Cost by Tier'!$K$5:$K$124,'Cost by Tier'!$C$5:$C$124,$C14,'Cost by Tier'!$E$5:$E$124,"EE")+SUMIFS('Cost by Tier'!$K$5:$K$124,'Cost by Tier'!$C$5:$C$124,$C14,'Cost by Tier'!$E$5:$E$124,"ES")+2*SUMIFS('Cost by Tier'!$K$5:$K$124,'Cost by Tier'!$C$5:$C$124,$C14,'Cost by Tier'!$E$5:$E$124,"FAM") -> 2981.21 | H14: =G14*12 -> 35774.52 | I14: =F14+H14 -> 70574.52 | J14: =SUMIFS('Cost by Tier'!$Q$5:$Q$124,'Cost by Tier'!$C$5:$C$124,$C14,'Cost by Tier'!$E$5:$E$124,"EE")+SUMIFS('Cost by Tier'!$Q$5:$Q$124,'Cost by Tier'!$C$5:$C$124,$C14,'Cost by Tier'!$E$5:$E$124,"ES")+2*SUMIFS('Cost by Tier'!$Q$5:$Q$124,'Cost by Tier'!$C$5:$C$124,$C14,'Cost by Tier'!$E$5:$E$124,"FAM") -> 84774.52 | K14: =F14-Assumptions!$D$14 -> 0
A15: ADP | B15: OA EPO 8000-80% ValueINT | C15: ADP|OA EPO 8000-80% ValueINT | D15: =INDEX('Plan Design'!$E$5:$E$34,MATCH($C15,'Plan Design'!$C$5:$C$34,0)) -> N | E15: =SUMIFS('Cost by Tier'!$J$5:$J$124,'Cost by Tier'!$C$5:$C$124,$C15,'Cost by Tier'!$E$5:$E$124,"EE")+SUMIFS('Cost by Tier'!$J$5:$J$124,'Cost by Tier'!$C$5:$C$124,$C15,'Cost by Tier'!$E$5:$E$124,"ES")+2*SUMIFS('Cost by Tier'!$J$5:$J$124,'Cost by Tier'!$C$5:$C$124,$C15,'Cost by Tier'!$E$5:$E$124,"FAM") -> 2900 | F15: =E15*12 -> 34800 | G15: =SUMIFS('Cost by Tier'!$K$5:$K$124,'Cost by Tier'!$C$5:$C$124,$C15,'Cost by Tier'!$E$5:$E$124,"EE")+SUMIFS('Cost by Tier'!$K$5:$K$124,'Cost by Tier'!$C$5:$C$124,$C15,'Cost by Tier'!$E$5:$E$124,"ES")+2*SUMIFS('Cost by Tier'!$K$5:$K$124,'Cost by Tier'!$C$5:$C$124,$C15,'Cost by Tier'!$E$5:$E$124,"FAM") -> 597.22 | H15: =G15*12 -> 7166.64 | I15: =F15+H15 -> 41966.64 | J15: =SUMIFS('Cost by Tier'!$Q$5:$Q$124,'Cost by Tier'!$C$5:$C$124,$C15,'Cost by Tier'!$E$5:$E$124,"EE")+SUMIFS('Cost by Tier'!$Q$5:$Q$124,'Cost by Tier'!$C$5:$C$124,$C15,'Cost by Tier'!$E$5:$E$124,"ES")+2*SUMIFS('Cost by Tier'!$Q$5:$Q$124,'Cost by Tier'!$C$5:$C$124,$C15,'Cost by Tier'!$E$5:$E$124,"FAM") -> 77166.64 | K15: =F15-Assumptions!$D$14 -> 0
A16: TriNet | B16: Aetna ACO 6500 AZ | C16: TriNet|Aetna ACO 6500 AZ | D16: =INDEX('Plan Design'!$E$5:$E$34,MATCH($C16,'Plan Design'!$C$5:$C$34,0)) -> N | E16: =SUMIFS('Cost by Tier'!$J$5:$J$124,'Cost by Tier'!$C$5:$C$124,$C16,'Cost by Tier'!$E$5:$E$124,"EE")+SUMIFS('Cost by Tier'!$J$5:$J$124,'Cost by Tier'!$C$5:$C$124,$C16,'Cost by Tier'!$E$5:$E$124,"ES")+2*SUMIFS('Cost by Tier'!$J$5:$J$124,'Cost by Tier'!$C$5:$C$124,$C16,'Cost by Tier'!$E$5:$E$124,"FAM") -> 2900 | F16: =E16*12 -> 34800 | G16: =SUMIFS('Cost by Tier'!$K$5:$K$124,'Cost by Tier'!$C$5:$C$124,$C16,'Cost by Tier'!$E$5:$E$124,"EE")+SUMIFS('Cost by Tier'!$K$5:$K$124,'Cost by Tier'!$C$5:$C$124,$C16,'Cost by Tier'!$E$5:$E$124,"ES")+2*SUMIFS('Cost by Tier'!$K$5:$K$124,'Cost by Tier'!$C$5:$C$124,$C16,'Cost by Tier'!$E$5:$E$124,"FAM") -> 706 | H16: =G16*12 -> 8472 | I16: =F16+H16 -> 43272 | J16: =SUMIFS('Cost by Tier'!$Q$5:$Q$124,'Cost by Tier'!$C$5:$C$124,$C16,'Cost by Tier'!$E$5:$E$124,"EE")+SUMIFS('Cost by Tier'!$Q$5:$Q$124,'Cost by Tier'!$C$5:$C$124,$C16,'Cost by Tier'!$E$5:$E$124,"ES")+2*SUMIFS('Cost by Tier'!$Q$5:$Q$124,'Cost by Tier'!$C$5:$C$124,$C16,'Cost by Tier'!$E$5:$E$124,"FAM") -> 60972 | K16: =F16-Assumptions!$D$14 -> 0
... A34: Angle | B34: ANG TRAD 1000/2000 | C34: Angle|ANG TRAD 1000/2000 | D34: =INDEX('Plan Design'!$E$5:$E$34,MATCH($C34,'Plan Design'!$C$5:$C$34,0)) -> N | E34: =SUMIFS('Cost by Tier'!$J$5:$J$124,'Cost by Tier'!$C$5:$C$124,$C34,'Cost by Tier'!$E$5:$E$124,"EE")+SUMIFS('Cost by Tier'!$J$5:$J$124,'Cost by Tier'!$C$5:$C$124,$C34,'Cost by Tier'!$E$5:$E$124,"ES")+2*SUMIFS('Cost by Tier'!$J$5:$J$124,'Cost by Tier'!$C$5:$C$124,$C34,'Cost by Tier'!$E$5:$E$124,"FAM") -> 2900 | F34: =E34*12 -> 34800 | G34: =SUMIFS('Cost by Tier'!$K$5:$K$124,'Cost by Tier'!$C$5:$C$124,$C34,'Cost by Tier'!$E$5:$E$124,"EE")+SUMIFS('Cost by Tier'!$K$5:$K$124,'Cost by Tier'!$C$5:$C$124,$C34,'Cost by Tier'!$E$5:$E$124,"ES")+2*SUMIFS('Cost by Tier'!$K$5:$K$124,'Cost by Tier'!$C$5:$C$124,$C34,'Cost by Tier'!$E$5:$E$124,"FAM") -> 2180.84 | H34: =G34*12 -> 26170.08 | I34: =F34+H34 -> 60970.08 | J34: =SUMIFS('Cost by Tier'!$Q$5:$Q$124,'Cost by Tier'!$C$5:$C$124,$C34,'Cost by Tier'!$E$5:$E$124,"EE")+SUMIFS('Cost by Tier'!$Q$5:$Q$124,'Cost by Tier'!$C$5:$C$124,$C34,'Cost by Tier'!$E$5:$E$124,"ES")+2*SUMIFS('Cost by Tier'!$Q$5:$Q$124,'Cost by Tier'!$C$5:$C$124,$C34,'Cost by Tier'!$E$5:$E$124,"FAM") -> 40170.08 | K34: =F34-Assumptions!$D$14 -> 0
A36: Onyx's cost is flat across every plan within a vendor, because the contribution is a fixed dollar amount and no vendor's floor exceeds it. Choosing a richer plan costs Onyx nothing extra and costs the employee the whole difference.
A37: Medical premium only. Admin fees, workers' compensation, setup fees, dental, vision, life and disability are excluded - see the Steven report for employer-only all-in cost.

Sheet By Employee
A1: Every plan, priced for each Onyx enrollee
A2: Josephine is included for reference at family coverage even though she is waiving. Steven's enrollment is still undecided.
A4: Employee | B4: Tier | C4: Code | D4: Vendor | E4: Plan | F4: Key | G4: HSA | H4: Monthly premium | I4: Onyx $/mo | J4: Employee $/mo | K4: Employee $/yr | L4: Deductible | M4: OOP max | N4: Worst case $/yr
A5: Steven Nikolov | B5: Family | C5: FAM | D5: ADP | E5: EPO HDHP 2000-100Copay TIF | F5: ADP|EPO HDHP 2000-100Copay TIF | G5: =INDEX('Cost by Tier'!$F$5:$F$124,MATCH($F5&"|"&$C5,'Cost by Tier'!$R$5:$R$124,0)) -> Y | H5: =INDEX('Cost by Tier'!$G$5:$G$124,MATCH($F5&"|"&$C5,'Cost by Tier'!$R$5:$R$124,0)) -> 1986.04 | I5: =INDEX('Cost by Tier'!$J$5:$J$124,MATCH($F5&"|"&$C5,'Cost by Tier'!$R$5:$R$124,0)) -> 1000 | J5: =INDEX('Cost by Tier'!$K$5:$K$124,MATCH($F5&"|"&$C5,'Cost by Tier'!$R$5:$R$124,0)) -> 986.04 | K5: =INDEX('Cost by Tier'!$M$5:$M$124,MATCH($F5&"|"&$C5,'Cost by Tier'!$R$5:$R$124,0)) -> 11832.48 | L5: =INDEX('Cost by Tier'!$O$5:$O$124,MATCH($F5&"|"&$C5,'Cost by Tier'!$R$5:$R$124,0)) -> 4000 | M5: =INDEX('Cost by Tier'!$P$5:$P$124,MATCH($F5&"|"&$C5,'Cost by Tier'!$R$5:$R$124,0)) -> 7000 | N5: =INDEX('Cost by Tier'!$Q$5:$Q$124,MATCH($F5&"|"&$C5,'Cost by Tier'!$R$5:$R$124,0)) -> 18832.48
A6: Steven Nikolov | B6: Family | C6: FAM | D6: ADP | E6: EPO HDHP 2500-100Copay TIF | F6: ADP|EPO HDHP 2500-100Copay TIF | G6: =INDEX('Cost by Tier'!$F$5:$F$124,MATCH($F6&"|"&$C6,'Cost by Tier'!$R$5:$R$124,0)) -> Y | H6: =INDEX('Cost by Tier'!$G$5:$G$124,MATCH($F6&"|"&$C6,'Cost by Tier'!$R$5:$R$124,0)) -> 1881.29 | I6: =INDEX('Cost by Tier'!$J$5:$J$124,MATCH($F6&"|"&$C6,'Cost by Tier'!$R$5:$R$124,0)) -> 1000 | J6: =INDEX('Cost by Tier'!$K$5:$K$124,MATCH($F6&"|"&$C6,'Cost by Tier'!$R$5:$R$124,0)) -> 881.29 | K6: =INDEX('Cost by Tier'!$M$5:$M$124,MATCH($F6&"|"&$C6,'Cost by Tier'!$R$5:$R$124,0)) -> 10575.48 | L6: =INDEX('Cost by Tier'!$O$5:$O$124,MATCH($F6&"|"&$C6,'Cost by Tier'!$R$5:$R$124,0)) -> 5000 | M6: =INDEX('Cost by Tier'!$P$5:$P$124,MATCH($F6&"|"&$C6,'Cost by Tier'!$R$5:$R$124,0)) -> 7000 | N6: =INDEX('Cost by Tier'!$Q$5:$Q$124,MATCH($F6&"|"&$C6,'Cost by Tier'!$R$5:$R$124,0)) -> 17575.48
A7: Steven Nikolov | B7: Family | C7: FAM | D7: ADP | E7: NATIONAL OA MC 500-80% | F7: ADP|NATIONAL OA MC 500-80% | G7: =INDEX('Cost by Tier'!$F$5:$F$124,MATCH($F7&"|"&$C7,'Cost by Tier'!$R$5:$R$124,0)) -> N | H7: =INDEX('Cost by Tier'!$G$5:$G$124,MATCH($F7&"|"&$C7,'Cost by Tier'!$R$5:$R$124,0)) -> 2737.01 | I7: =INDEX('Cost by Tier'!$J$5:$J$124,MATCH($F7&"|"&$C7,'Cost by Tier'!$R$5:$R$124,0)) -> 1000 | J7: =INDEX('Cost by Tier'!$K$5:$K$124,MATCH($F7&"|"&$C7,'Cost by Tier'!$R$5:$R$124,0)) -> 1737.01 | K7: =INDEX('Cost by Tier'!$M$5:$M$124,MATCH($F7&"|"&$C7,'Cost by Tier'!$R$5:$R$124,0)) -> 20844.12 | L7: =INDEX('Cost by Tier'!$O$5:$O$124,MATCH($F7&"|"&$C7,'Cost by Tier'!$R$5:$R$124,0)) -> 1000 | M7: =INDEX('Cost by Tier'!$P$5:$P$124,MATCH($F7&"|"&$C7,'Cost by Tier'!$R$5:$R$124,0)) -> 7000 | N7: =INDEX('Cost by Tier'!$Q$5:$Q$124,MATCH($F7&"|"&$C7,'Cost by Tier'!$R$5:$R$124,0)) -> 27844.12
A8: Steven Nikolov | B8: Family | C8: FAM | D8: ADP | E8: NATIONAL OA MC 1000-80% | F8: ADP|NATIONAL OA MC 1000-80% | G8: =INDEX('Cost by Tier'!$F$5:$F$124,MATCH($F8&"|"&$C8,'Cost by Tier'!$R$5:$R$124,0)) -> N | H8: =INDEX('Cost by Tier'!$G$5:$G$124,MATCH($F8&"|"&$C8,'Cost by Tier'!$R$5:$R$124,0)) -> 2381.46 | I8: =INDEX('Cost by Tier'!$J$5:$J$124,MATCH($F8&"|"&$C8,'Cost by Tier'!$R$5:$R$124,0)) -> 1000 | J8: =INDEX('Cost by Tier'!$K$5:$K$124,MATCH($F8&"|"&$C8,'Cost by Tier'!$R$5:$R$124,0)) -> 1381.46 | K8: =INDEX('Cost by Tier'!$M$5:$M$124,MATCH($F8&"|"&$C8,'Cost by Tier'!$R$5:$R$124,0)) -> 16577.52 | L8: =INDEX('Cost by Tier'!$O$5:$O$124,MATCH($F8&"|"&$C8,'Cost by Tier'!$R$5:$R$124,0)) -> 2000 | M8: =INDEX('Cost by Tier'!$P$5:$P$124,MATCH($F8&"|"&$C8,'Cost by Tier'!$R$5:$R$124,0)) -> 9000 | N8: =INDEX('Cost by Tier'!$Q$5:$Q$124,MATCH($F8&"|"&$C8,'Cost by Tier'!$R$5:$R$124,0)) -> 25577.52
A9: Steven Nikolov | B9: Family | C9: FAM | D9: ADP | E9: OA EPO HDHP 3500-80% | F9: ADP|OA EPO HDHP 3500-80% | G9: =INDEX('Cost by Tier'!$F$5:$F$124,MATCH($F9&"|"&$C9,'Cost by Tier'!$R$5:$R$124,0)) -> Y | H9: =INDEX('Cost by Tier'!$G$5:$G$124,MATCH($F9&"|"&$C9,'Cost by Tier'!$R$5:$R$124,0)) -> 1519.36 | I9: =INDEX('Cost by Tier'!$J$5:$J$124,MATCH($F9&"|"&$C9,'Cost by Tier'!$R$5:$R$124,0)) -> 1000 | J9: =INDEX('Cost by Tier'!$K$5:$K$124,MATCH($F9&"|"&$C9,'Cost by Tier'!$R$5:$R$124,0)) -> 519.36 | K9: =INDEX('Cost by Tier'!$M$5:$M$124,MATCH($F9&"|"&$C9,'Cost by Tier'!$R$5:$R$124,0)) -> 6232.32 | L9: =INDEX('Cost by Tier'!$O$5:$O$124,MATCH($F9&"|"&$C9,'Cost by Tier'!$R$5:$R$124,0)) -> 7000 | M9: =INDEX('Cost by Tier'!$P$5:$P$124,MATCH($F9&"|"&$C9,'Cost by Tier'!$R$5:$R$124,0)) -> 12700 | N9: =INDEX('Cost by Tier'!$Q$5:$Q$124,MATCH($F9&"|"&$C9,'Cost by Tier'!$R$5:$R$124,0)) -> 18932.32
A10: Steven Nikolov | B10: Family | C10: FAM | D10: ADP | E10: OA EPO 500-80% | F10: ADP|OA EPO 500-80% | G10: =INDEX('Cost by Tier'!$F$5:$F$124,MATCH($F10&"|"&$C10,'Cost by Tier'!$R$5:$R$124,0)) -> N | H10: =INDEX('Cost by Tier'!$G$5:$G$124,MATCH($F10&"|"&$C10,'Cost by Tier'!$R$5:$R$124,0)) -> 2558.21 | I10: =INDEX('Cost by Tier'!$J$5:$J$124,MATCH($F10&"|"&$C10,'Cost by Tier'!$R$5:$R$124,0)) -> 1000 | J10: =INDEX('Cost by Tier'!$K$5:$K$124,MATCH($F10&"|"&$C10,'Cost by Tier'!$R$5:$R$124,0)) -> 1558.21 | K10: =INDEX('Cost by Tier'!$M$5:$M$124,MATCH($F10&"|"&$C10,'Cost by Tier'!$R$5:$R$124,0)) -> 18698.52 | L10: =INDEX('Cost by Tier'!$O$5:$O$124,MATCH($F10&"|"&$C10,'Cost by Tier'!$R$5:$R$124,0)) -> 1000 | M10: =INDEX('Cost by Tier'!$P$5:$P$124,MATCH($F10&"|"&$C10,'Cost by Tier'!$R$5:$R$124,0)) -> 7000 | N10: =INDEX('Cost by Tier'!$Q$5:$Q$124,MATCH($F10&"|"&$C10,'Cost by Tier'!$R$5:$R$124,0)) -> 25698.52
A11: Steven Nikolov | B11: Family | C11: FAM | D11: ADP | E11: OA EPO 1000-80% | F11: ADP|OA EPO 1000-80% | G11: =INDEX('Cost by Tier'!$F$5:$F$124,MATCH($F11&"|"&$C11,'Cost by Tier'!$R$5:$R$124,0)) -> N | H11: =INDEX('Cost by Tier'!$G$5:$G$124,MATCH($F11&"|"&$C11,'Cost by Tier'!$R$5:$R$124,0)) -> 2322.36 | I11: =INDEX('Cost by Tier'!$J$5:$J$124,MATCH($F11&"|"&$C11,'Cost by Tier'!$R$5:$R$124,0)) -> 1000 | J11: =INDEX('Cost by Tier'!$K$5:$K$124,MATCH($F11&"|"&$C11,'Cost by Tier'!$R$5:$R$124,0)) -> 1322.36 | K11: =INDEX('Cost by Tier'!$M$5:$M$124,MATCH($F11&"|"&$C11,'Cost by Tier'!$R$5:$R$124,0)) -> 15868.32 | L11: =INDEX('Cost by Tier'!$O$5:$O$124,MATCH($F11&"|"&$C11,'Cost by Tier'!$R$5:$R$124,0)) -> 2000 | M11: =INDEX('Cost by Tier'!$P$5:$P$124,MATCH($F11&"|"&$C11,'Cost by Tier'!$R$5:$R$124,0)) -> 9000 | N11: =INDEX('Cost by Tier'!$Q$5:$Q$124,MATCH($F11&"|"&$C11,'Cost by Tier'!$R$5:$R$124,0)) -> 24868.32
A12: Steven Nikolov | B12: Family | C12: FAM | D12: ADP | E12: OA EPO 1500-100% | F12: ADP|OA EPO 1500-100% | G12: =INDEX('Cost by Tier'!$F$5:$F$124,MATCH($F12&"|"&$C12,'Cost by Tier'!$R$5:$R$124,0)) -> N | H12: =INDEX('Cost by Tier'!$G$5:$G$124,MATCH($F12&"|"&$C12,'Cost by Tier'!$R$5:$R$124,0)) -> 2309.12 | I12: =INDEX('Cost by Tier'!$J$5:$J$124,MATCH($F12&"|"&$C12,'Cost by Tier'!$R$5:$R$124,0)) -> 1000 | J12: =INDEX('Cost by Tier'!$K$5:$K$124,MATCH($F12&"|"&$C12,'Cost by Tier'!$R$5:$R$124,0)) -> 1309.12 | K12: =INDEX('Cost by Tier'!$M$5:$M$124,MATCH($F12&"|"&$C12,'Cost by Tier'!$R$5:$R$124,0)) -> 15709.44 | L12: =INDEX('Cost by Tier'!$O$5:$O$124,MATCH($F12&"|"&$C12,'Cost by Tier'!$R$5:$R$124,0)) -> 3000 | M12: =INDEX('Cost by Tier'!$P$5:$P$124,MATCH($F12&"|"&$C12,'Cost by Tier'!$R$5:$R$124,0)) -> 10000 | N12: =INDEX('Cost by Tier'!$Q$5:$Q$124,MATCH($F12&"|"&$C12,'Cost by Tier'!$R$5:$R$124,0)) -> 25709.44
A13: Steven Nikolov | B13: Family | C13: FAM | D13: ADP | E13: OA EPO HDHP 6000-80% | F13: ADP|OA EPO HDHP 6000-80% | G13: =INDEX('Cost by Tier'!$F$5:$F$124,MATCH($F13&"|"&$C13,'Cost by Tier'!$R$5:$R$124,0)) -> Y | H13: =INDEX('Cost by Tier'!$G$5:$G$124,MATCH($F13&"|"&$C13,'Cost by Tier'!$R$5:$R$124,0)) -> 1357.49 | I13: =INDEX('Cost by Tier'!$J$5:$J$124,MATCH($F13&"|"&$C13,'Cost by Tier'!$R$5:$R$124,0)) -> 1000 | J13: =INDEX('Cost by Tier'!$K$5:$K$124,MATCH($F13&"|"&$C13,'Cost by Tier'!$R$5:$R$124,0)) -> 357.49 | K13: =INDEX('Cost by Tier'!$M$5:$M$124,MATCH($F13&"|"&$C13,'Cost by Tier'!$R$5:$R$124,0)) -> 4289.88 | L13: =INDEX('Cost by Tier'!$O$5:$O$124,MATCH($F13&"|"&$C13,'Cost by Tier'!$R$5:$R$124,0)) -> 12000 | M13: =INDEX('Cost by Tier'!$P$5:$P$124,MATCH($F13&"|"&$C13,'Cost by Tier'!$R$5:$R$124,0)) -> 13000 | N13: =INDEX('Cost by Tier'!$Q$5:$Q$124,MATCH($F13&"|"&$C13,'Cost by Tier'!$R$5:$R$124,0)) -> 17289.88
A14: Steven Nikolov | B14: Family | C14: FAM | D14: ADP | E14: OA EPO 3000-80% | F14: ADP|OA EPO 3000-80% | G14: =INDEX('Cost by Tier'!$F$5:$F$124,MATCH($F14&"|"&$C14,'Cost by Tier'!$R$5:$R$124,0)) -> N | H14: =INDEX('Cost by Tier'!$G$5:$G$124,MATCH($F14&"|"&$C14,'Cost by Tier'!$R$5:$R$124,0)) -> 1949.92 | I14: =INDEX('Cost by Tier'!$J$5:$J$124,MATCH($F14&"|"&$C14,'Cost by Tier'!$R$5:$R$124,0)) -> 1000 | J14: =INDEX('Cost by Tier'!$K$5:$K$124,MATCH($F14&"|"&$C14,'Cost by Tier'!$R$5:$R$124,0)) -> 949.92 | K14: =INDEX('Cost by Tier'!$M$5:$M$124,MATCH($F14&"|"&$C14,'Cost by Tier'!$R$5:$R$124,0)) -> 11399.04 | L14: =INDEX('Cost by Tier'!$O$5:$O$124,MATCH($F14&"|"&$C14,'Cost by Tier'!$R$5:$R$124,0)) -> 6000 | M14: =INDEX('Cost by Tier'!$P$5:$P$124,MATCH($F14&"|"&$C14,'Cost by Tier'!$R$5:$R$124,0)) -> 14000 | N14: =INDEX('Cost by Tier'!$Q$5:$Q$124,MATCH($F14&"|"&$C14,'Cost by Tier'!$R$5:$R$124,0)) -> 25399.04
A15: Steven Nikolov | B15: Family | C15: FAM | D15: ADP | E15: OA EPO 8000-80% ValueINT | F15: ADP|OA EPO 8000-80% ValueINT | G15: =INDEX('Cost by Tier'!$F$5:$F$124,MATCH($F15&"|"&$C15,'Cost by Tier'!$R$5:$R$124,0)) -> N | H15: =INDEX('Cost by Tier'!$G$5:$G$124,MATCH($F15&"|"&$C15,'Cost by Tier'!$R$5:$R$124,0)) -> 1159.51 | I15: =INDEX('Cost by Tier'!$J$5:$J$124,MATCH($F15&"|"&$C15,'Cost by Tier'!$R$5:$R$124,0)) -> 1000 | J15: =INDEX('Cost by Tier'!$K$5:$K$124,MATCH($F15&"|"&$C15,'Cost by Tier'!$R$5:$R$124,0)) -> 159.51 | K15: =INDEX('Cost by Tier'!$M$5:$M$124,MATCH($F15&"|"&$C15,'Cost by Tier'!$R$5:$R$124,0)) -> 1914.12 | L15: =INDEX('Cost by Tier'!$O$5:$O$124,MATCH($F15&"|"&$C15,'Cost by Tier'!$R$5:$R$124,0)) -> 16000 | M15: =INDEX('Cost by Tier'!$P$5:$P$124,MATCH($F15&"|"&$C15,'Cost by Tier'!$R$5:$R$124,0)) -> 20000 | N15: =INDEX('Cost by Tier'!$Q$5:$Q$124,MATCH($F15&"|"&$C15,'Cost by Tier'!$R$5:$R$124,0)) -> 21914.12
A16: Steven Nikolov | B16: Family | C16: FAM | D16: TriNet | E16: Aetna ACO 6500 AZ | F16: TriNet|Aetna ACO 6500 AZ | G16: =INDEX('Cost by Tier'!$F$5:$F$124,MATCH($F16&"|"&$C16,'Cost by Tier'!$R$5:$R$124,0)) -> N | H16: =INDEX('Cost by Tier'!$G$5:$G$124,MATCH($F16&"|"&$C16,'Cost by Tier'!$R$5:$R$124,0)) -> 1166 | I16: =INDEX('Cost by Tier'!$J$5:$J$124,MATCH($F16&"|"&$C16,'Cost by Tier'!$R$5:$R$124,0)) -> 1000 | J16: =INDEX('Cost by Tier'!$K$5:$K$124,MATCH($F16&"|"&$C16,'Cost by Tier'!$R$5:$R$124,0)) -> 166 | K16: =INDEX('Cost by Tier'!$M$5:$M$124,MATCH($F16&"|"&$C16,'Cost by Tier'!$R$5:$R$124,0)) -> 1992 | L16: =INDEX('Cost by Tier'!$O$5:$O$124,MATCH($F16&"|"&$C16,'Cost by Tier'!$R$5:$R$124,0)) -> 13000 | M16: =INDEX('Cost by Tier'!$P$5:$P$124,MATCH($F16&"|"&$C16,'Cost by Tier'!$R$5:$R$124,0)) -> 15000 | N16: =INDEX('Cost by Tier'!$Q$5:$Q$124,MATCH($F16&"|"&$C16,'Cost by Tier'!$R$5:$R$124,0)) -> 16992
... A154: Josephine Mack (waiving) | B154: Family | C154: FAM | D154: Angle | E154: ANG TRAD 1000/2000 | F154: Angle|ANG TRAD 1000/2000 | G154: =INDEX('Cost by Tier'!$F$5:$F$124,MATCH($F154&"|"&$C154,'Cost by Tier'!$R$5:$R$124,0)) -> N | H154: =INDEX('Cost by Tier'!$G$5:$G$124,MATCH($F154&"|"&$C154,'Cost by Tier'!$R$5:$R$124,0)) -> 1693.61 | I154: =INDEX('Cost by Tier'!$J$5:$J$124,MATCH($F154&"|"&$C154,'Cost by Tier'!$R$5:$R$124,0)) -> 1000 | J154: =INDEX('Cost by Tier'!$K$5:$K$124,MATCH($F154&"|"&$C154,'Cost by Tier'!$R$5:$R$124,0)) -> 693.61 | K154: =INDEX('Cost by Tier'!$M$5:$M$124,MATCH($F154&"|"&$C154,'Cost by Tier'!$R$5:$R$124,0)) -> 8323.32 | L154: =INDEX('Cost by Tier'!$O$5:$O$124,MATCH($F154&"|"&$C154,'Cost by Tier'!$R$5:$R$124,0)) -> 2000 | M154: =INDEX('Cost by Tier'!$P$5:$P$124,MATCH($F154&"|"&$C154,'Cost by Tier'!$R$5:$R$124,0)) -> 4000 | N154: =INDEX('Cost by Tier'!$Q$5:$Q$124,MATCH($F154&"|"&$C154,'Cost by Tier'!$R$5:$R$124,0)) -> 12323.32
A156: Sorted by employee, then in the order the vendor lists its plans. Use the filter on row 4 to isolate one person or one vendor.
